<?xml version="1.0"?>
<!--
  沃姆 EPGC-50-150 二指平行夹爪 xacro 宏。
  行程 50mm（每指 ±25mm），负载 3kg。
  尺寸实测（2026-07）：法兰面→指尖 112.7mm = 转接板12(挂载origin)
  + 本体95 + 滑块段5.7(滑块-本体缝隙1.7+滑块4)。当前直接用滑块夹持、无加长手指；
  若后续加装手指，改 finger_len 并重标 width_offset 即可。
  ⚠️ body_w/body_h、finger_w/finger_thick 仍为占位（仅碰撞体，待实测）。
  定义:
    <prefix>base_link   夹爪基座（固连到机械臂法兰 tool0）
    <prefix>left_finger / right_finger  两指（prismatic）
    <prefix>grasp_tcp   夹爪工具中心点（两指中间、指尖处）—— 抓取规划用此 frame
-->
<robot xmlns:xacro="http://www.ros.org/wiki/xacro">

  <xacro:macro name="worm_epgc50" params="prefix parent *origin">

    <!-- ===== 尺寸（Z向两项已实测；横向宽高为占位待测）===== -->
    <xacro:property name="body_len" value="0.095"/>   <!-- 实测：安装面→滑块根 -->
    <!-- 本体不规则，用 66x53 外廓包络盒近似（实测）；假定 66 沿开合方向(X) -->
    <xacro:property name="body_w"   value="0.066"/>
    <xacro:property name="body_h"   value="0.053"/>
    <xacro:property name="finger_len"   value="0.0057"/> <!-- 实测：缝隙1.7+滑块4 -->
    <xacro:property name="finger_w"     value="0.010"/>  <!-- 占位 -->
    <xacro:property name="finger_thick" value="0.008"/>  <!-- 占位 -->
    <xacro:property name="stroke_half"  value="0.025"/> <!-- 单指行程 25mm -->
    <xacro:property name="mass_body"    value="0.30"/>
    <!-- TCP 距基座(沿Z)的距离 = 本体长 + 指长 -->
    <xacro:property name="tcp_z" value="${body_len + finger_len}"/>

    <!-- 基座，固连到 parent(tool0) -->
    <joint name="${prefix}base_joint" type="fixed">
      <parent link="${parent}"/>
      <child link="${prefix}base_link"/>
      <xacro:insert_block name="origin"/>
    </joint>

    <link name="${prefix}base_link">
      <visual>
        <origin xyz="0 0 ${body_len/2}" rpy="0 0 0"/>
        <geometry><box size="${body_w} ${body_h} ${body_len}"/></geometry>
        <material name="worm_gray"><color rgba="0.3 0.3 0.3 1"/></material>
      </visual>
      <collision>
        <origin xyz="0 0 ${body_len/2}" rpy="0 0 0"/>
        <geometry><box size="${body_w} ${body_h} ${body_len}"/></geometry>
      </collision>
      <inertial>
        <mass value="${mass_body}"/>
        <inertia ixx="1e-4" iyy="1e-4" izz="1e-4" ixy="0" ixz="0" iyz="0"/>
      </inertial>
    </link>

    <!-- 左指：沿 +X 平移 -->
    <joint name="${prefix}left_finger_joint" type="prismatic">
      <parent link="${prefix}base_link"/>
      <child link="${prefix}left_finger"/>
      <origin xyz="0 0 ${body_len}" rpy="0 0 0"/>
      <axis xyz="1 0 0"/>
      <limit lower="0.0" upper="${stroke_half}" effort="50" velocity="0.1"/>
    </joint>
    <link name="${prefix}left_finger">
      <visual>
        <origin xyz="0 0 ${finger_len/2}" rpy="0 0 0"/>
        <geometry><box size="${finger_thick} ${finger_w} ${finger_len}"/></geometry>
        <material name="worm_gray"/>
      </visual>
      <collision>
        <origin xyz="0 0 ${finger_len/2}" rpy="0 0 0"/>
        <geometry><box size="${finger_thick} ${finger_w} ${finger_len}"/></geometry>
      </collision>
      <inertial>
        <mass value="0.02"/>
        <inertia ixx="1e-6" iyy="1e-6" izz="1e-6" ixy="0" ixz="0" iyz="0"/>
      </inertial>
    </link>

    <!-- 右指：沿 -X 平移（mimic 左指）-->
    <joint name="${prefix}right_finger_joint" type="prismatic">
      <parent link="${prefix}base_link"/>
      <child link="${prefix}right_finger"/>
      <origin xyz="0 0 ${body_len}" rpy="0 0 0"/>
      <axis xyz="-1 0 0"/>
      <limit lower="0.0" upper="${stroke_half}" effort="50" velocity="0.1"/>
      <mimic joint="${prefix}left_finger_joint" multiplier="1.0" offset="0.0"/>
    </joint>
    <link name="${prefix}right_finger">
      <visual>
        <origin xyz="0 0 ${finger_len/2}" rpy="0 0 0"/>
        <geometry><box size="${finger_thick} ${finger_w} ${finger_len}"/></geometry>
        <material name="worm_gray"/>
      </visual>
      <collision>
        <origin xyz="0 0 ${finger_len/2}" rpy="0 0 0"/>
        <geometry><box size="${finger_thick} ${finger_w} ${finger_len}"/></geometry>
      </collision>
      <inertial>
        <mass value="0.02"/>
        <inertia ixx="1e-6" iyy="1e-6" izz="1e-6" ixy="0" ixz="0" iyz="0"/>
      </inertial>
    </link>

    <!-- TCP：两指中间、指尖处。抓取规划用此 frame（grasp_executor 的 tcp_link）-->
    <link name="${prefix}grasp_tcp"/>
    <joint name="${prefix}grasp_tcp_joint" type="fixed">
      <parent link="${prefix}base_link"/>
      <child link="${prefix}grasp_tcp"/>
      <origin xyz="0 0 ${tcp_z}" rpy="0 0 0"/>
    </joint>

  </xacro:macro>
</robot>
